<?xml version="1.0"?>
<robot name="arm_robot">
  <!--作業台に固定されているようにするための架空のリンク"world"-->
  <link name="world"/>

  <!--台座のモデリング-->
  <link name="base_link">
    <!--外観-->
    <visual>
      <geometry>
        <cylinder length="0.05" radius="0.1"/>
      </geometry>
      <material name="silver1">
	<color rgba="0.25 0.25 0.25 1"/>
      </material>
      <origin rpy="0 0 0" xyz="0 0 0.025"/>
    </visual>
    <!--物理的特性-->
    <!--干渉-->
    <collision>
      <geometry>
        <cylinder length="0.05" radius="0.1"/>
      </geometry>
      <origin rpy="0 0 0" xyz="0 0 0.025"/>
    </collision>
    <!--慣性-->
    <inertial>
      <mass value="1.0"/>
      <origin rpy="0 0 0" xyz="0 0 0.025"/>
      <inertia ixx="0.0027" iyy="0.0027" izz="0.005" ixy="0" ixz="0" iyz="0"/>
    </inertial>
  </link>
  <!--台座と作業台（world）をつなぐ関節-->
  <joint name="fixed" type="fixed">
    <parent link="world"/>
    <child link="base_link"/>
  </joint>
	
  <!--胴体のモデリング-->
  <link name="torso">
    <!--外観-->
    <visual>
      <geometry>
        <cylinder length="0.5" radius="0.05"/>
      </geometry>
      <material name="silver2">
        <color rgba="0.50 0.50 0.50 1"/>
      </material>
      <origin rpy="0 0 0" xyz="0 0 0.25"/>
    </visual>
    <!--物理的特性-->
    <!--干渉-->
    <collision>
      <geometry>
        <cylinder length="0.5" radius="0.05"/>
      </geometry>
      <origin rpy="0 0 0" xyz="0 0 0.25"/>
    </collision>
    <!--慣性-->
    <inertial>
      <mass value="1.0"/>
      <origin rpy="0 0 0" xyz="0 0 0.25"/>
      <inertia ixx="0.02146" iyy="0.02146" izz="0.00125" ixy="0" ixz="0" iyz="0"/>
    </inertial>
  </link>
  <!--胴体と台座をつなぐ関節（腰）-->
  <joint name="joint1" type="continuous">
    <axis xyz="0 0 1"/>
    <parent link="base_link"/>
    <child link="torso"/>
    <origin rpy="0 0 1.5708" xyz="0.0 0.0 0.05"/>
  </joint>
  	
  <!--上腕のモデリング-->
  <link name="upper_arm">
    <!--外観-->
    <visual>
      <geometry>
        <cylinder length="0.4" radius="0.05"/>
      </geometry>
      <material name="silver1"/>
      <origin rpy="0 0 0" xyz="0 0 0.2"/>
    </visual>
    <!--物理的特性-->
    <!--干渉-->
    <collision>
      <geometry>
        <cylinder length="0.4" radius="0.05"/>
      </geometry>
      <origin rpy="0 0 0" xyz="0 0 0.2"/>
    </collision>
    <!--慣性-->
    <inertial>
      <mass value="1.0"/>
      <origin rpy="0 0 0" xyz="0 0 0.2"/>
      <inertia ixx="0.01396" iyy="0.01396" izz="0.00125" ixy="0" ixz="0" iyz="0"/>
    </inertial>
  </link>
  <!--上腕と胴体をつなぐ関節（肩）-->
  <joint name="joint2" type="continuous">
    <axis xyz="0 1 0"/>
    <parent link="torso"/>
    <child link="upper_arm"/>
    <origin rpy="0 1.5708 0" xyz="0.0 -0.1 0.45"/>
  </joint>

  <!--前腕のモデリング-->
  <link name="lower_arm">
    <!--外観-->
    <visual>
      <geometry>
        <cylinder length="0.4" radius="0.05"/>
      </geometry>
      <material name="silver2"/>
      <origin rpy="0 0 0" xyz="0 0 0.2"/>
    </visual>
    <!--物理的特性-->
    <!--干渉-->
    <collision>
      <geometry>
        <cylinder length="0.4" radius="0.05"/>
      </geometry>
      <origin rpy="0 0 0" xyz="0 0 0.2"/>
    </collision>
    <!--慣性-->
    <inertial>
      <mass value="1.0"/>
      <origin rpy="0 0 0" xyz="0 0 0.2"/>
      <inertia ixx="0.01396" iyy="0.01396" izz="0.00125" ixy="0" ixz="0" iyz="0"/>
    </inertial>
  </link>
  <!--前腕と上腕をつなぐ関節（肘）-->
  <joint name="joint3" type="continuous">
    <axis xyz="0 1 0"/>
    <parent link="upper_arm"/>
    <child link="lower_arm"/>
    <origin rpy="0 0 0" xyz="0.0 0.1 0.35"/>
  </joint>

  <!--手のモデリング-->
  <link name="hand">
    <!--外観-->
    <visual>
      <geometry>
        <box size="0.05 0.05 0.05"/>
      </geometry>
      <material name="silver1"/>
    </visual>
    <!--物理的特性-->
    <!--干渉-->
    <collision>
      <geometry>
        <box size="0.05 0.05 0.05"/>
      </geometry>
    </collision>
    <!--慣性-->
    <inertial>
      <mass value="1.0"/>
      <inertia ixx="0.00042" iyy="0.00042" izz="0.00042" ixy="0" ixz="0" iyz="0"/>
    </inertial>
  </link>
  <!--手と前腕をつなぐ関節（手首）-->
  <joint name="joint4" type="continuous">
    <axis xyz="0 1 0"/>
    <parent link="lower_arm"/>
    <child link="hand"/>
    <origin rpy="0 0 0" xyz="0.0 0.0 0.425"/>
  </joint>

  <!--トランスミッションの追加-->
  <!--腰関節用-->
  <transmission name="tran0">
    <type>transmission_interface/SimpleTransmission</type>
    <!--関節の指定-->
    <joint name="joint1">
      <hardwareInterface>hardware_interface/PositionJointInterface</hardwareInterface>
    </joint>
    <!--アクチュエータの定義（ギア比1の減速機）-->
    <actuator name="motor0">
      <hardwareInterface>PositionJointInterface</hardwareInterface>
      <mechanicalReduction>1</mechanicalReduction>
    </actuator>
  </transmission>

  <!--肩関節用-->
  <transmission name="tran1">
    <type>transmission_interface/SimpleTransmission</type>
    <!--関節の指定-->
    <joint name="joint2">
      <hardwareInterface>hardware_interface/PositionJointInterface</hardwareInterface>
    </joint>
    <!--アクチュエータの定義（ギア比1の減速機）-->
    <actuator name="motor1">
      <hardwareInterface>PositionJointInterface</hardwareInterface>
      <mechanicalReduction>1</mechanicalReduction>
    </actuator>
  </transmission>
    
  <!--肘関節用-->
  <transmission name="tran2">
    <type>transmission_interface/SimpleTransmission</type>
    <!--関節の指定-->
    <joint name="joint3">
      <hardwareInterface>hardware_interface/PositionJointInterface</hardwareInterface>
    </joint>
    <!--アクチュエータの定義（ギア比1の減速機）-->
    <actuator name="motor2">
      <hardwareInterface>PositionJointInterface</hardwareInterface>
      <mechanicalReduction>1</mechanicalReduction>
    </actuator>
  </transmission>
    
  <!--手首関節用-->
  <transmission name="tran3">
    <type>transmission_interface/SimpleTransmission</type>
    <!--関節の指定-->
    <joint name="joint4">
      <hardwareInterface>hardware_interface/PositionJointInterface</hardwareInterface>
    </joint>
    <!--アクチュエータの定義（ギア比1の減速機）-->
    <actuator name="motor3">
      <hardwareInterface>PositionJointInterface</hardwareInterface>
      <mechanicalReduction>1</mechanicalReduction>
    </actuator>
  </transmission>

  <!--ros_controlプラグインをロード-->
  <!-- <gazebo>
    <plugin name="control" filename="libgazebo_ros2_control.so"/>
  </gazebo> -->

  <!-- ros2_control -->
  <ros2_control name="GazeboSystem" type="system">
    <hardware>
      <plugin>gz_ros2_control/GazeboSimSystem</plugin>
    </hardware>
  </ros2_control>

  <gazebo>
    <plugin
      filename="gz-sim-joint-state-publisher-system"
      name="gz::sim::systems::JointStatePublisher">
    </plugin>
  </gazebo>
  <gazebo>
    <plugin
      filename="gz-sim-joint-trajectory-controller-system"
      name="gz::sim::systems::JointTrajectoryController">
      <joint_name>joint1</joint_name>
      <initial_position>0.0</initial_position>
      <position_p_gain>20</position_p_gain>
      <position_i_gain>0.4</position_i_gain>
      <position_d_gain>1.0</position_d_gain>
      <position_i_min>-1</position_i_min>
      <position_i_max>1</position_i_max>
      <position_cmd_min>-1</position_cmd_min>
      <position_cmd_max>1</position_cmd_max>
      <position_cmd_offset>0</position_cmd_offset>

      <joint_name>joint2</joint_name>
      <initial_position>0.0</initial_position>
      <position_p_gain>10</position_p_gain>
      <position_i_gain>0.2</position_i_gain>
      <position_d_gain>0.5</position_d_gain>
      <position_i_min>-1</position_i_min>
      <position_i_max>1</position_i_max>
      <position_cmd_min>-1</position_cmd_min>
      <position_cmd_max>1</position_cmd_max>
      <position_cmd_offset>0</position_cmd_offset>

      <joint_name>joint3</joint_name>
      <initial_position>0.0</initial_position>
      <position_p_gain>10</position_p_gain>
      <position_i_gain>0.2</position_i_gain>
      <position_d_gain>0.5</position_d_gain>
      <position_i_min>-1</position_i_min>
      <position_i_max>1</position_i_max>
      <position_cmd_min>-1</position_cmd_min>
      <position_cmd_max>1</position_cmd_max>
      <position_cmd_offset>0</position_cmd_offset>

      <joint_name>joint4</joint_name>
      <initial_position>0.0</initial_position>
      <position_p_gain>10</position_p_gain>
      <position_i_gain>0.2</position_i_gain>
      <position_d_gain>0.5</position_d_gain>
      <position_i_min>-1</position_i_min>
      <position_i_max>1</position_i_max>
      <position_cmd_min>-1</position_cmd_min>
      <position_cmd_max>1</position_cmd_max>
      <position_cmd_offset>0</position_cmd_offset>

      <!-- Gazebo側が軌道メッセージを受け取るトピック名 -->
      <topic>arm_trajectory</topic>
    </plugin>
  </gazebo>
  <gazebo>
  <plugin filename="gz-sim-joint-position-controller-system"
          name="gz::sim::systems::JointPositionController">
    <joint_name>joint1</joint_name>
    <initial_velocity>0.0</initial_velocity>
    <p_gain>50</p_gain>
    <i_gain>0.1</i_gain>
    <d_gain>2.0</d_gain>
    <i_max>1</i_max>
    <i_min>-1</i_min>
    <cmd_max>1000</cmd_max>
    <cmd_min>-1000</cmd_min>
    <topic>joint1_position_cmd</topic>
  </plugin>

  <plugin filename="gz-sim-joint-position-controller-system"
          name="gz::sim::systems::JointPositionController">
    <joint_name>joint2</joint_name>
    <initial_velocity>0.0</initial_velocity>
    <p_gain>50</p_gain>
    <i_gain>0.1</i_gain>
    <d_gain>2.0</d_gain>
    <i_max>1</i_max>
    <i_min>-1</i_min>
    <cmd_max>1000</cmd_max>
    <cmd_min>-1000</cmd_min>
    <topic>joint2_position_cmd</topic>
  </plugin>

  <plugin filename="gz-sim-joint-position-controller-system"
          name="gz::sim::systems::JointPositionController">
    <joint_name>joint3</joint_name>
    <initial_velocity>0.0</initial_velocity>
    <p_gain>50</p_gain>
    <i_gain>0.1</i_gain>
    <d_gain>2.0</d_gain>
    <i_max>1</i_max>
    <i_min>-1</i_min>
    <cmd_max>1000</cmd_max>
    <cmd_min>-1000</cmd_min>
    <topic>joint3_position_cmd</topic>
  </plugin>

    <plugin filename="gz-sim-joint-position-controller-system"
          name="gz::sim::systems::JointPositionController">
    <joint_name>joint4</joint_name>
    <initial_velocity>0.0</initial_velocity>
    <p_gain>50</p_gain>
    <i_gain>0.1</i_gain>
    <d_gain>2.0</d_gain>
    <i_max>1</i_max>
    <i_min>-1</i_min>
    <cmd_max>1000</cmd_max>
    <cmd_min>-1000</cmd_min>
    <topic>joint4_position_cmd</topic>
  </plugin>
</gazebo>


</robot>

